data/realtime/test.csv
Side,Price,Quantity,Total
ASK,0.00279,1,0.00279
ASK,0.0027,2,0.0054
ASK,0.00269,3,0.00807
ASK,0.00262,4,0.01048
ASK,0.00261,5,0.01305
ASK,0.00259,6,0.01554
ASK,0.00249,7,0.01743
ASK,0.00243,8,0.01944
ASK,0.00229,9,0.02061
ASK,0.00221,3,0.00663
BID,0.0022,1,0.0022
BID,0.00219,2,0.00438
BID,0.00218,3,0.00654
BID,0.00217,4,0.00868
BID,0.00209,5,0.01045
BID,0.00202,6,0.01212
BID,0.002,7,0.014
BID,0.00199,8,0.01592
BID,0.00191,9,0.01719
BID,0.0018,2,0.0036
